Workbook

Sheet respuestas_simuladas_redes_soci
A1: id_respuesta | B1: Carrera | C1: Plataforma | D1: Tiempo | E1: Proposito | F1: Mayor_uso | G1: Dispositivo | H1: Productividad
A2: 1 | B2: Ingeniería Industrial | C2: WhatsApp | D2: Más de 8 horas | E2: Entretenimiento | F2: Tarde | G2: Computador | H2: Positivamente
A3: 2 | B3: Ingeniería de Sistemas | C3: YouTube | D3: 5 a 6 horas | E3: Entretenimiento | F3: Tarde | G3: Tableta | H3: Muy negativamente
A4: 3 | B4: Otra | C4: YouTube | D4: Más de 8 horas | E4: Comunicación | F4: Mañana | G4: Celular | H4: Negativamente
A5: 4 | B5: Ingeniería de Sistemas | C5: Instagram | D5: 5 a 6 horas | E5: Entretenimiento | F5: Noche | G5: Celular | H5: Negativamente
A6: 5 | B6: Ingeniería de Sistemas | C6: Instagram | D6: 5 a 6 horas | E6: Entretenimiento | F6: Noche | G6: Celular | H6: No tiene influencia
A7: 6 | B7: Ingeniería Mecánica | C7: Instagram | D7: 1 a 2 horas | E7: Entretenimiento | F7: Noche | G7: Celular | H7: No tiene influencia
A8: 7 | B8: Ingeniería de Sistemas | C8: Instagram | D8: 5 a 6 horas | E8: Entretenimiento | F8: Mañana | G8: Celular | H8: No tiene influencia
A9: 8 | B9: Ingeniería Industrial | C9: Instagram | D9: Más de 8 horas | E9: Noticias e información | F9: Mañana | G9: Celular | H9: No tiene influencia
A10: 9 | B10: Ingeniería de Sistemas | C10: Instagram | D10: 5 a 6 horas | E10: Entretenimiento | F10: Noche | G10: Celular | H10: No tiene influencia
A11: 10 | B11: Ingeniería de Sistemas | C11: Instagram | D11: 7 a 8 horas | E11: Entretenimiento | F11: Durante todo el día | G11: Celular | H11: Muy negativamente
A12: 11 | B12: Otra | C12: TikTok | D12: 5 a 6 horas | E12: Entretenimiento | F12: Tarde | G12: Celular | H12: Muy negativamente
A13: 12 | B13: Ingeniería de Sistemas | C13: Instagram | D13: Más de 8 horas | E13: Estudio o aprendizaje | F13: Noche | G13: Celular | H13: Negativamente
... A101: 100 | B101: Ingeniería de Sistemas | C101: Instagram | D101: 7 a 8 horas | E101: Trabajo o emprendimiento | F101: Tarde | G101: Celular | H101: Negativamente

Sheet Analisis
A1: Plataforma | B1: Cantidad
A2: TikTok | B2: =COUNTIF(respuestas_simuladas_redes_soci!C:C,Analisis!A2) -> 42
A3: Instagram | B3: =COUNTIF(respuestas_simuladas_redes_soci!C:C,Analisis!A3) -> 32
A4: WhatsApp | B4: =COUNTIF(respuestas_simuladas_redes_soci!C:C,Analisis!A4) -> 9
A5: YouTube | B5: =COUNTIF(respuestas_simuladas_redes_soci!C:C,Analisis!A5) -> 11
A6: Facebook | B6: =COUNTIF(respuestas_simuladas_redes_soci!C:C,Analisis!A6) -> 6
A7: X | B7: =COUNTIF(respuestas_simuladas_redes_soci!C:C,Analisis!A7) -> 0
A8: Otra | B8: =COUNTIF(respuestas_simuladas_redes_soci!C:C,Analisis!A8) -> 0
B9: =SUM(B2+B3+B4+B5+B6+B7+B8) -> 100
A16: Tiempo Diario | B16: Cantidad
A17: Menos de 1 hora | B17: =COUNTIF(respuestas_simuladas_redes_soci!D:D,Analisis!A17) -> 0
A18: 1 a 2 horas | B18: =COUNTIF(respuestas_simuladas_redes_soci!D:D,Analisis!A18) -> 14
A19: 3 a 4 horas | B19: =COUNTIF(respuestas_simuladas_redes_soci!D:D,Analisis!A19) -> 7
A20: 5 a 6 horas | B20: =COUNTIF(respuestas_simuladas_redes_soci!D:D,Analisis!A20) -> 25
A21: 7 a 8 horas | B21: =COUNTIF(respuestas_simuladas_redes_soci!D:D,Analisis!A21) -> 24
A22: Más de 8 horas | B22: =COUNTIF(respuestas_simuladas_redes_soci!D:D,Analisis!A22) -> 30
B23: =SUM(B18,B19,B17,B20,B21,B22) -> 100
A30: Propósito principal | B30: Cantidad
A31: Entretenimiento | B31: =COUNTIF(respuestas_simuladas_redes_soci!E:E,Analisis!A31) -> 48
A32: Comunicación | B32: =COUNTIF(respuestas_simuladas_redes_soci!E:E,Analisis!A32) -> 27
A33: Estudio o aprendizaje | B33: =COUNTIF(respuestas_simuladas_redes_soci!E:E,Analisis!A33) -> 8
A34: Noticias e información | B34: =COUNTIF(respuestas_simuladas_redes_soci!E:E,Analisis!A34) -> 9
A35: Trabajo o emprendimiento | B35: =COUNTIF(respuestas_simuladas_redes_soci!E:E,Analisis!A35) -> 8
B36: =SUM(B31,B32,B33,B34,B35) -> 100
A45: Momento de mayor uso | B45: Cantidad
A46: Mañana | B46: =COUNTIF(respuestas_simuladas_redes_soci!F:F,Analisis!A46) -> 13
A47: Tarde | B47: =COUNTIF(respuestas_simuladas_redes_soci!F:F,Analisis!A47) -> 29
A48: Noche | B48: =COUNTIF(respuestas_simuladas_redes_soci!F:F,Analisis!A48) -> 29
A49: Madrugada | B49: =COUNTIF(respuestas_simuladas_redes_soci!F:F,Analisis!A49) -> 0
A50: Durante todo el día | B50: =COUNTIF(respuestas_simuladas_redes_soci!F:F,Analisis!A50) -> 12
A51: Mediodía / almuerzo | B51: =COUNTIF(respuestas_simuladas_redes_soci!F:F,Analisis!A51) -> 17
B52: =SUM(B46,B47,B48,B49,B50,B51) -> 100
A61: Dispositivos | B61: Cantidad
A62: Celular | B62: =COUNTIF(respuestas_simuladas_redes_soci!G:G,Analisis!A62) -> 88
A63: Computador | B63: =COUNTIF(respuestas_simuladas_redes_soci!G:G,Analisis!A63) -> 3
A64: Tableta | B64: =COUNTIF(respuestas_simuladas_redes_soci!G:G,Analisis!A64) -> 9
A65: Otro | B65: =COUNTIF(respuestas_simuladas_redes_soci!G:G,Analisis!A65) -> 0
B66: =SUM(B62,B63,B64,B65) -> 100
A76: Influencia | B76: Cantidad
A77: Positivamente | B77: =COUNTIF(respuestas_simuladas_redes_soci!H:H,Analisis!A77) -> 7
...
